<?xml version="1.0" ?>
<!-- =================================================================================== -->
<!-- |    This document was autogenerated by xacro from hdt_standalone.xacro           | -->
<!-- |    EDITING THIS FILE BY HAND IS NOT RECOMMENDED                                 | -->
<!-- =================================================================================== -->
<robot name="hdt" xmlns:xacro="http://www.ros.org/wiki/xacro">
  <!-- <gazebo>
    <plugin name="gazebo_ros_control" filename="libgazebo_ros_control.so">
      <robotNamespace>/hdt_arm</robotNamespace>
      <robotSimType>gazebo_ros_control/DefaultRobotHWSim</robotSimType>
      <legacyModeNS>true</legacyModeNS>
    </plugin>
  </gazebo> -->
  <!-- camera -->
  <!-- <gazebo reference="camera_link">
    <sensor name="kinect_camera" type="depth">
      <update_rate>20</update_rate>
      <camera>
        <horizontal_fov>1.047198</horizontal_fov>
        <image>
          <width>640</width>
          <height>480</height>
          <format>R8G8B8</format>
        </image>
        <clip>
          <near>0.05</near>
          <far>3</far>
        </clip>
      </camera>
      <plugin name="kinect_controller" filename="libgazebo_ros_openni_kinect.so">
        <baseline>0.2</baseline>
        <alwaysOn>true</alwaysOn>
        <updateRate>1.0</updateRate>
        <cameraName>kinect_ir</cameraName>
        <imageTopicName>/kinect/color/image_raw</imageTopicName>
        <cameraInfoTopicName>/kinect/color/camera_info</cameraInfoTopicName>
        <depthImageTopicName>/kinect/depth/image_raw</depthImageTopicName>
        <depthImageInfoTopicName>/kinect/depth/camera_info</depthImageInfoTopicName>
        <pointCloudTopicName>/kinect/depth/points</pointCloudTopicName>
        <frameName>camera_link_optical</frameName>
        <pointCloudCutoff>0.5</pointCloudCutoff>
        <pointCloudCutoffMax>3.0</pointCloudCutoffMax>
        <distortionK1>0.00000001</distortionK1>
        <distortionK2>0.00000001</distortionK2>
        <distortionK3>0.00000001</distortionK3>
        <distortionT1>0.00000001</distortionT1>
        <distortionT2>0.00000001</distortionT2>
        <CxPrime>0</CxPrime>
        <Cx>0</Cx>
        <Cy>0</Cy>
        <focalLength>0</focalLength>
        <hackBaseline>0</hackBaseline>
      </plugin>
    </sensor>
  </gazebo> -->
  <link name="world"/>
  <transmission name="/trans1">
    <type>transmission_interface/SimpleTransmission</type>
    <joint name="/drive1_joint">
      <hardwareInterface>PositionJointInterface</hardwareInterface>
    </joint>
    <actuator name="motor1">
      <hardwareInterface>PositionJointInterface</hardwareInterface>
      <mechanicalReduction>1</mechanicalReduction>
    </actuator>
  </transmission>
  <transmission name="/trans2">
    <type>transmission_interface/SimpleTransmission</type>
    <joint name="/drive2_joint">
      <hardwareInterface>PositionJointInterface</hardwareInterface>
    </joint>
    <actuator name="motor2">
      <hardwareInterface>PositionJointInterface</hardwareInterface>
      <mechanicalReduction>1</mechanicalReduction>
    </actuator>
  </transmission>
  <transmission name="/trans3">
    <type>transmission_interface/SimpleTransmission</type>
    <joint name="/drive3_joint">
      <hardwareInterface>PositionJointInterface</hardwareInterface>
    </joint>
    <actuator name="motor3">
      <hardwareInterface>PositionJointInterface</hardwareInterface>
      <mechanicalReduction>1</mechanicalReduction>
    </actuator>
  </transmission>
  <transmission name="/trans4">
    <type>transmission_interface/SimpleTransmission</type>
    <joint name="/drive4_joint">
      <hardwareInterface>PositionJointInterface</hardwareInterface>
    </joint>
    <actuator name="motor4">
      <hardwareInterface>PositionJointInterface</hardwareInterface>
      <mechanicalReduction>1</mechanicalReduction>
    </actuator>
  </transmission>
  <transmission name="/trans5">
    <type>transmission_interface/SimpleTransmission</type>
    <joint name="/drive5_joint">
      <hardwareInterface>PositionJointInterface</hardwareInterface>
    </joint>
    <actuator name="motor5">
      <hardwareInterface>PositionJointInterface</hardwareInterface>
      <mechanicalReduction>1</mechanicalReduction>
    </actuator>
  </transmission>
  <transmission name="/trans6">
    <type>transmission_interface/SimpleTransmission</type>
    <joint name="/drive6_joint">
      <hardwareInterface>PositionJointInterface</hardwareInterface>
    </joint>
    <actuator name="motor6">
      <hardwareInterface>PositionJointInterface</hardwareInterface>
      <mechanicalReduction>1</mechanicalReduction>
    </actuator>
  </transmission>
  <transmission name="/trans7">
    <type>transmission_interface/SimpleTransmission</type>
    <joint name="/pincer_joint">
      <hardwareInterface>PositionJointInterface</hardwareInterface>
    </joint>
    <actuator name="motor7">
      <hardwareInterface>PositionJointInterface</hardwareInterface>
      <mechanicalReduction>1</mechanicalReduction>
    </actuator>
  </transmission>
  <transmission name="/trans8">
    <type>transmission_interface/SimpleTransmission</type>
    <joint name="/pincer_joint2">
      <hardwareInterface>PositionJointInterface</hardwareInterface>
    </joint>
    <actuator name="motor8">
      <hardwareInterface>PositionJointInterface</hardwareInterface>
      <mechanicalReduction>1</mechanicalReduction>
    </actuator>
  </transmission>
  <gazebo reference="/pedestal_link">
    <selfCollide>false</selfCollide>
    <maxContacts>1</maxContacts>
    <!-- <material>Gazebo/Black</material> -->
    <mu1>0.61</mu1>
    <mu2>0.61</mu2>
  </gazebo>
  <gazebo reference="/drive1_link">
    <selfCollide>false</selfCollide>
    <maxContacts>1</maxContacts>
    <!-- <material>Gazebo/Black</material> -->
    <mu1>0.61</mu1>
    <mu2>0.61</mu2>
  </gazebo>
  <gazebo reference="/drive2_link">
    <selfCollide>false</selfCollide>
    <maxContacts>1</maxContacts>
    <!-- <material>Gazebo/Black</material> -->
    <mu1>0.61</mu1>
    <mu2>0.61</mu2>
  </gazebo>
  <gazebo reference="/humerus_link">
    <selfCollide>false</selfCollide>
    <maxContacts>1</maxContacts>
    <!-- <material>Gazebo/Black</material> -->
    <mu1>0.61</mu1>
    <mu2>0.61</mu2>
  </gazebo>
  <gazebo reference="/elbow_link">
    <selfCollide>false</selfCollide>
    <maxContacts>1</maxContacts>
    <!-- <material>Gazebo/Black</material> -->
    <mu1>0.61</mu1>
    <mu2>0.61</mu2>
  </gazebo>
  <gazebo reference="/drive3_link">
    <selfCollide>false</selfCollide>
    <maxContacts>1</maxContacts>
    <!-- <material>Gazebo/Black</material> -->
    <mu1>0.61</mu1>
    <mu2>0.61</mu2>
  </gazebo>
  <gazebo reference="/drive4_link">
    <selfCollide>false</selfCollide>
    <maxContacts>1</maxContacts>
    <!-- <material>Gazebo/Black</material> -->
    <mu1>0.61</mu1>
    <mu2>0.61</mu2>
  </gazebo>
  <gazebo reference="/wrist_link">
    <selfCollide>false</selfCollide>
    <maxContacts>1</maxContacts>
    <!-- <material>Gazebo/Black</material> -->
    <mu1>0.61</mu1>
    <mu2>0.61</mu2>
  </gazebo>
  <gazebo reference="/drive5_link">
    <selfCollide>false</selfCollide>
    <maxContacts>1</maxContacts>
    <!-- <material>Gazebo/Black</material> -->
    <mu1>0.61</mu1>
    <mu2>0.61</mu2>
  </gazebo>
  <gazebo reference="/drive6_link">
    <selfCollide>false</selfCollide>
    <maxContacts>1</maxContacts>
    <!-- <material>Gazebo/Black</material> -->
    <mu1>0.61</mu1>
    <mu2>0.61</mu2>
  </gazebo>
  <gazebo reference="/pincer_link">
    <selfCollide>false</selfCollide>
    <maxContacts>1</maxContacts>
    <!-- <material>Gazebo/Black</material> -->
    <mu1>0.61</mu1>
    <mu2>0.61</mu2>
  </gazebo>
  <gazebo reference="/pincer_link2">
    <selfCollide>false</selfCollide>
    <maxContacts>1</maxContacts>
    <!-- <material>Gazebo/Black</material> -->
    <mu1>0.61</mu1>
    <mu2>0.61</mu2>
  </gazebo>
  <!-- <gazebo reference="${namespace}/endpoint_link">
    <material>Gazebo/Black</material>
    <mu1>0.61</mu1>
    <mu2>0.61</mu2>
  </gazebo> -->
  <!-- camera -->
  <joint name="/camera_joint" type="fixed">
    <!-- <axis xyz="0 1 0"/> -->
    <parent link="/drive6_link"/>
    <child link="/camera_link"/>
  </joint>
  <link name="/camera_link">
    <collision>
      <origin rpy="0 0 0" xyz="0 0 0"/>
      <geometry>
        <box size="0.01 0.01 0.01"/>
      </geometry>
    </collision>
    <visual>
      <origin rpy="0 0 0" xyz="0 0 0"/>
      <geometry>
        <box size="0.01 0.01 0.01"/>
      </geometry>
      <material name="red"/>
    </visual>
    <inertial>
      <mass value="1e-5"/>
      <origin rpy="0 0 0" xyz="0 0 0"/>
      <inertia ixx="1e-6" ixy="0" ixz="0" iyy="1e-6" iyz="0" izz="1e-6"/>
    </inertial>
  </link>
  <!-- generate an optical frame http://www.ros.org/reps/rep-0103.html#suffix-frames
        so that ros and opencv can operate on the camera frame correctly -->
  <joint name="/camera_optical_joint" type="fixed">
    <!-- these values have to be these values otherwise the gazebo camera image
              won't be aligned properly with the frame it is supposedly originating from -->
    <origin rpy="-1.57079632679 0 -1.57079632679" xyz="0 0 0"/>
    <parent link="/camera_link"/>
    <child link="/camera_link_optical"/>
  </joint>
  <link name="/camera_link_optical">
      </link>
  <!-- materials -->
  <material name="black1">
    <color rgba="0.78431372549 0.78431372549 0.78431372549 1.0"/>
  </material>
  <material name="grey1">
    <color rgba="0.250980392157 0.250980392157 0.250980392157 1.0"/>
  </material>
  <material name="yellow1">
    <color rgba="0.941176470588 0.878431372549 0.250980392157 1.0"/>
  </material>
  <!-- segment 0 -->
  <!-- <link name="${namespace}/base_link"/> -->
  <!-- pedestal -->
  <!-- <joint name="${namespace}/pedestal_joint" type="fixed">
            <origin xyz="0 0 0" rpy="0 0 0"/>
            <parent link="${namespace}/base_link"/>
            <child link="${namespace}/pedestal_link"/>
        </joint> -->
  <link name="/pedestal_link">
    <collision>
      <origin rpy="0 0 0" xyz="0 0 0"/>
      <geometry>
        <mesh filename="package://hdt_angler_description/meshes/H026994 - A35 M-2 PEDESTAL ASSY - SHAREABLE.STL"/>
      </geometry>
    </collision>
    <visual>
      <origin rpy="0 0 0" xyz="0 0 0"/>
      <geometry>
        <mesh filename="package://hdt_angler_description/meshes/H026994 - A35 M-2 PEDESTAL ASSY - SHAREABLE.STL"/>
      </geometry>
      <material name="black1"/>
    </visual>
    <inertial>
      <origin rpy="0 0 0" xyz="0 0 0"/>
      <mass value="0.11"/>
      <inertia ixx="0.05" ixy="0.01" ixz="0.01" iyy="0.05" iyz="0.01" izz="0.05"/>
    </inertial>
  </link>
  <!-- drive 1 -->
  <joint name="/drive1_joint" type="revolute">
    <axis xyz="0 0 1"/>
    <limit effort="60.0" lower="-6.28318530718" upper="6.28318530718" velocity="0.785398163397"/>
    <origin rpy="0 0 -1.57079632679" xyz="0 0 0.08335"/>
    <parent link="/pedestal_link"/>
    <child link="/drive1_link"/>
    <dynamics damping="0.7" friction="0.0"/>
  </joint>
  <link name="/drive1_link">
    <collision>
      <origin rpy="0 0 0" xyz="0 0 0"/>
      <geometry>
        <mesh filename="package://hdt_angler_description/meshes/H024840 - A35 M-2 DRIVE MODULE, SHAREABLE.STL"/>
      </geometry>
    </collision>
    <visual>
      <origin rpy="0 0 0" xyz="0 0 0"/>
      <geometry>
        <mesh filename="package://hdt_angler_description/meshes/H024840 - A35 M-2 DRIVE MODULE, SHAREABLE.STL"/>
      </geometry>
      <material name="black1"/>
    </visual>
    <inertial>
      <origin rpy="0 0 0" xyz="0 0 0"/>
      <mass value="0.11"/>
      <inertia ixx="0.05" ixy="0.01" ixz="0.01" iyy="0.05" iyz="0.01" izz="0.05"/>
    </inertial>
  </link>
  <!-- drive 2 -->
  <joint name="/drive2_joint" type="revolute">
    <axis xyz="0 0 1"/>
    <limit effort="60.0" lower="-1.57079632679" upper="1.57079632679" velocity="0.785398163397"/>
    <origin rpy="0 -1.57079632679 0" xyz="0.07155 0 0"/>
    <parent link="/drive1_link"/>
    <child link="/drive2_link"/>
    <dynamics damping="0.7" friction="0.0"/>
  </joint>
  <link name="/drive2_link">
    <collision>
      <origin rpy="3.14159265359 0 0" xyz="0 0 0"/>
      <geometry>
        <mesh filename="package://hdt_angler_description/meshes/H024840 - A35 M-2 DRIVE MODULE, SHAREABLE.STL"/>
      </geometry>
    </collision>
    <visual>
      <origin rpy="3.14159265359 0 0" xyz="0 0 0"/>
      <geometry>
        <mesh filename="package://hdt_angler_description/meshes/H024840 - A35 M-2 DRIVE MODULE, SHAREABLE.STL"/>
      </geometry>
      <material name="black1"/>
    </visual>
    <inertial>
      <origin rpy="3.14159265359 0 0" xyz="0 0 0"/>
      <mass value="0.11"/>
      <inertia ixx="0.05" ixy="0.01" ixz="0.01" iyy="0.05" iyz="0.01" izz="0.05"/>
    </inertial>
  </link>
  <!-- humerus -->
  <joint name="/humerus_joint" type="fixed">
    <origin rpy="0 0 0" xyz="0.17855 0 0"/>
    <parent link="/drive2_link"/>
    <child link="/humerus_link"/>
  </joint>
  <link name="/humerus_link">
    <collision>
      <origin rpy="0 0 0" xyz="0 0 0"/>
      <geometry>
        <mesh filename="package://hdt_angler_description/meshes/H024847 - A35 M-2 PROXIMAL TUBE ASSY - SHAREABLE.STL"/>
      </geometry>
    </collision>
    <visual>
      <origin rpy="0 0 0" xyz="0 0 0"/>
      <geometry>
        <mesh filename="package://hdt_angler_description/meshes/H024847 - A35 M-2 PROXIMAL TUBE ASSY - SHAREABLE.STL"/>
      </geometry>
      <material name="black1"/>
    </visual>
    <inertial>
      <origin rpy="0 0 0" xyz="0 0 0"/>
      <mass value="0.11"/>
      <inertia ixx="0.05" ixy="0.01" ixz="0.01" iyy="0.05" iyz="0.01" izz="0.05"/>
    </inertial>
  </link>
  <!-- elbow -->
  <joint name="/elbow_joint" type="fixed">
    <origin rpy="0 0 0" xyz="0.17855 0 0"/>
    <parent link="/humerus_link"/>
    <child link="/elbow_link"/>
  </joint>
  <link name="/elbow_link">
    <collision>
      <origin rpy="0 3.14159265359 0" xyz="0 0 0"/>
      <geometry>
        <mesh filename="package://hdt_angler_description/meshes/H024840 - A35 M-2 DRIVE MODULE, SHAREABLE.STL"/>
      </geometry>
    </collision>
    <visual>
      <origin rpy="0 3.14159265359 0" xyz="0 0 0"/>
      <geometry>
        <mesh filename="package://hdt_angler_description/meshes/H024840 - A35 M-2 DRIVE MODULE, SHAREABLE.STL"/>
      </geometry>
      <material name="black1"/>
    </visual>
    <inertial>
      <origin rpy="0 3.14159265359 0" xyz="0 0 0"/>
      <mass value="0.11"/>
      <inertia ixx="0.05" ixy="0.01" ixz="0.01" iyy="0.05" iyz="0.01" izz="0.05"/>
    </inertial>
  </link>
  <!-- drive 3 -->
  <joint name="/drive3_joint" type="revolute">
    <axis xyz="0 0 1"/>
    <!-- position limits to match parameter settings on actuator -->
    <limit effort="60.0" lower="-4.49" upper="1.35" velocity="0.785398163397"/>
    <origin rpy="0 0 0" xyz="0 0 0.07155"/>
    <parent link="/elbow_link"/>
    <child link="/drive3_link"/>
    <dynamics damping="0.7" friction="0.0"/>
  </joint>
  <link name="/drive3_link">
    <collision>
      <origin rpy="0 1.57079632679 -1.57079632679" xyz="0 0 0"/>
      <geometry>
        <mesh filename="package://hdt_angler_description/meshes/H024840 - A35 M-2 DRIVE MODULE, SHAREABLE.STL"/>
      </geometry>
    </collision>
    <visual>
      <origin rpy="0 1.57079632679 -1.57079632679" xyz="0 0 0"/>
      <geometry>
        <mesh filename="package://hdt_angler_description/meshes/H024840 - A35 M-2 DRIVE MODULE, SHAREABLE.STL"/>
      </geometry>
      <material name="black1"/>
    </visual>
    <inertial>
      <origin rpy="0 1.57079632679 -1.57079632679" xyz="0 0 0"/>
      <mass value="0.11"/>
      <inertia ixx="0.05" ixy="0.01" ixz="0.01" iyy="0.05" iyz="0.01" izz="0.05"/>
    </inertial>
  </link>
  <!-- drive 4 -->
  <joint name="/drive4_joint" type="revolute">
    <axis xyz="0 0 1"/>
    <limit effort="60.0" lower="-6.28318530718" upper="6.28318530718" velocity="0.785398163397"/>
    <origin rpy="-1.57079632679 0 0" xyz="0 0.142 0"/>
    <parent link="/drive3_link"/>
    <child link="/drive4_link"/>
    <dynamics damping="0.7" friction="0.0"/>
  </joint>
  <link name="/drive4_link">
    <collision>
      <origin rpy="3.14159265359 0 0" xyz="0 0 0"/>
      <geometry>
        <mesh filename="package://hdt_angler_description/meshes/H024848 - A35 M-2 DISTAL TUBE ASSY - SHAREABLE.STL"/>
      </geometry>
    </collision>
    <visual>
      <origin rpy="3.14159265359 0 0" xyz="0 0 0"/>
      <geometry>
        <mesh filename="package://hdt_angler_description/meshes/H024848 - A35 M-2 DISTAL TUBE ASSY - SHAREABLE.STL"/>
      </geometry>
      <material name="black1"/>
    </visual>
    <inertial>
      <origin rpy="3.14159265359 0 0" xyz="0 0 0"/>
      <mass value="0.11"/>
      <inertia ixx="0.05" ixy="0.01" ixz="0.01" iyy="0.05" iyz="0.01" izz="0.05"/>
    </inertial>
  </link>
  <!-- wrist -->
  <joint name="/wrist_joint" type="fixed">
    <origin rpy="1.57079632679 -1.57079632679 3.14159265359" xyz="0 0 0.12955"/>
    <parent link="/drive4_link"/>
    <child link="/wrist_link"/>
  </joint>
  <link name="/wrist_link">
    <collision>
      <origin rpy="0 0 3.14159265359" xyz="0 0 0"/>
      <geometry>
        <mesh filename="package://hdt_angler_description/meshes/H024840 - A35 M-2 DRIVE MODULE, SHAREABLE.STL"/>
      </geometry>
    </collision>
    <visual>
      <origin rpy="0 0 3.14159265359" xyz="0 0 0"/>
      <geometry>
        <mesh filename="package://hdt_angler_description/meshes/H024840 - A35 M-2 DRIVE MODULE, SHAREABLE.STL"/>
      </geometry>
      <material name="black1"/>
    </visual>
    <inertial>
      <origin rpy="0 0 3.14159265359" xyz="0 0 0"/>
      <mass value="0.11"/>
      <inertia ixx="0.05" ixy="0.01" ixz="0.01" iyy="0.05" iyz="0.01" izz="0.05"/>
    </inertial>
  </link>
  <!-- drive 5 -->
  <joint name="/drive5_joint" type="revolute">
    <axis xyz="0 0 1"/>
    <limit effort="60.0" lower="-6.28318530718" upper="6.28318530718" velocity="0.785398163397"/>
    <origin rpy="3.14159265359 0 0" xyz="0 0 -0.07155"/>
    <parent link="/wrist_link"/>
    <child link="/drive5_link"/>
    <dynamics damping="0.7" friction="0.0"/>
  </joint>
  <link name="/drive5_link">
    <collision>
      <origin rpy="0 1.57079632679 3.14159265359" xyz="0 0 0"/>
      <geometry>
        <mesh filename="package://hdt_angler_description/meshes/H024840 - A35 M-2 DRIVE MODULE, SHAREABLE.STL"/>
      </geometry>
    </collision>
    <visual>
      <origin rpy="0 1.57079632679 3.14159265359" xyz="0 0 0"/>
      <geometry>
        <mesh filename="package://hdt_angler_description/meshes/H024840 - A35 M-2 DRIVE MODULE, SHAREABLE.STL"/>
      </geometry>
      <material name="black1"/>
    </visual>
    <inertial>
      <origin rpy="0 0 0" xyz="0 0 0"/>
      <mass value="0.11"/>
      <inertia ixx="0.05" ixy="0.01" ixz="0.01" iyy="0.05" iyz="0.01" izz="0.05"/>
    </inertial>
  </link>
  <!-- drive 6 -->
  <joint name="/drive6_joint" type="revolute">
    <axis xyz="0 0 1"/>
    <limit effort="60.0" lower="-6.28318530718" upper="6.28318530718" velocity="0.785398163397"/>
    <origin rpy="0 1.57079632679 0" xyz="0.0885 0 0"/>
    <parent link="/drive5_link"/>
    <child link="/drive6_link"/>
    <dynamics damping="0.7" friction="0.0"/>
  </joint>
  <link name="/drive6_link">
    <collision>
      <origin rpy="0 1.57079632679 -1.57079632679" xyz="0 0 0"/>
      <geometry>
        <mesh filename="package://hdt_angler_description/meshes/H024842 - A35 M-2 PINCER ASSY - SHAREABLE, UNDERWATER.STL"/>
      </geometry>
    </collision>
    <visual>
      <origin rpy="0 1.57079632679 -1.57079632679" xyz="0 0 0"/>
      <geometry>
        <mesh filename="package://hdt_angler_description/meshes/H024842 - A35 M-2 PINCER ASSY - SHAREABLE, UNDERWATER.STL"/>
      </geometry>
      <material name="black1"/>
    </visual>
    <inertial>
      <origin rpy="0 0 0" xyz="0 0 0"/>
      <mass value="0.11"/>
      <inertia ixx="0.05" ixy="0.01" ixz="0.01" iyy="0.05" iyz="0.01" izz="0.05"/>
    </inertial>
  </link>
  <!-- Pincers -->
  <joint name="/pincer_joint" type="revolute">
    <!-- <hdt id="10" kmin="75" kmax="150" inertia="0.075"/>		 -->
    <axis xyz="0 0 1"/>
    <limit effort="60.0" lower="-0.2" upper="0.9" velocity="0.5"/>
    <origin rpy="-1.57079632679 -1.57079632679 0" xyz="0.0135 0 0.0375"/>
    <parent link="/drive6_link"/>
    <child link="/pincer_link"/>
    <dynamics damping="0.7" friction="0.0"/>
  </joint>
  <link name="/pincer_link">
    <collision>
      <origin rpy="3.14159265359 0 0" xyz="0 0 0"/>
      <geometry>
        <mesh filename="package://hdt_angler_description/meshes/H022927 - A35 PINCER FINGER, LONG, OVERMOLD ASSY - SHAREABLE.STL"/>
      </geometry>
    </collision>
    <visual>
      <origin rpy="3.14159265359 0 0" xyz="0 0 0"/>
      <geometry>
        <mesh filename="package://hdt_angler_description/meshes/H022927 - A35 PINCER FINGER, LONG, OVERMOLD ASSY - SHAREABLE.STL"/>
      </geometry>
      <material name="black1"/>
    </visual>
    <inertial>
      <origin rpy="0 0 0" xyz="0 0 0"/>
      <mass value="0.11"/>
      <inertia ixx="0.05" ixy="0.01" ixz="0.01" iyy="0.05" iyz="0.01" izz="0.05"/>
    </inertial>
  </link>
  <!-- EE 2 -->
  <!-- THIS IS THE SECOND PINCER, NEEDS TO MOVE EQUAL BUT OPPOSITE AS PINCER 1 -->
  <joint name="/pincer_joint2" type="revolute">
    <!--<hdt id="10b" kmin="75" kmax="150" inertia="0.075"/>-->
    <axis xyz="0 0 1"/>
    <origin rpy="-1.57079632679 -1.57079632679 3.14159265359" xyz="-0.0135 0 0.0375"/>
    <parent link="/drive6_link"/>
    <child link="/pincer_link2"/>
    <calibration rising="0.0"/>
    <dynamics damping="0.7" friction="0.0"/>
    <limit effort="60.0" lower="-0.2" upper="1" velocity="0.5"/>
    <mimic joint="/pincer_joint" multiplier="1" offset="0.0"/>
  </joint>
  <link name="/pincer_link2">
    <collision>
      <origin rpy="3.14159265359 0 0" xyz="0 0 0"/>
      <geometry>
        <mesh filename="package://hdt_angler_description/meshes/H022927 - A35 PINCER FINGER, LONG, OVERMOLD ASSY - SHAREABLE.STL"/>
      </geometry>
    </collision>
    <visual>
      <origin rpy="3.14159265359 0 0" xyz="0 0 0"/>
      <geometry>
        <mesh filename="package://hdt_angler_description/meshes/H022927 - A35 PINCER FINGER, LONG, OVERMOLD ASSY - SHAREABLE.STL"/>
      </geometry>
      <material name="black1"/>
    </visual>
    <inertial>
      <origin rpy="0 0 0" xyz="0 0 0"/>
      <mass value="0.11"/>
      <inertia ixx="0.05" ixy="0.01" ixz="0.01" iyy="0.05" iyz="0.01" izz="0.05"/>
    </inertial>
  </link>
  <!-- endpoint -->
  <joint name="/endpoint_joint" type="fixed">
    <origin rpy="1.57079632679 -1.57079632679 0" xyz="0 0 0.1"/>
    <parent link="/drive6_link"/>
    <child link="/endpoint_link"/>
  </joint>
  <link name="/endpoint_link">
        </link>
  <joint name="/anchor" type="fixed">
    <parent link="world"/>
    <child link="/pedestal_link"/>
    <origin rpy="0 0 0" xyz="0 0 1.5"/>
    <!-- <axis xyz="0 1 0"/> -->
    <!-- <limit effort="0" lower="0" upper="0" velocity="0"/> -->
  </joint>
</robot>

